Workbook

Sheet Instructions
A1: Room A Hourly Usage Forecast (8 AM - 5 PM)
A3: What this model forecasts
A4: For each quarter of Year 4, how much of each hour (8-9 AM through 4-5 PM) Room A is expected to be in use on each weekday of a typical week.
A5: 100% = the room is booked for the whole hour; 50% = booked for half of it (e.g., a meeting starting at 12:30).
A7: How it works
A8: 1. Booking Log: every booking from one full mid-quarter week per quarter in each of the last three years (Week 5; Week 4 in summer), with start and end times.
A9: 2. Hourly Usage: the log is converted to the share of each hour that was booked, per year, quarter, and weekday. Overlapping bookings are capped at 100% of the hour.
A10: 3. Forecast: a weighted average of the three years (20% / 30% / 50%), times (1 + growth), capped at 100%.
A11: 4. current fall Actual: the same grid built from current fall Weeks 1, 2, and 4, so you can compare this fall with the forecast slot by slot.
A13: How to use
A14: Add bookings to the Booking Log (blue cells) to refine any quarter, e.g., a second sample week. Update the 'sample weeks' count on Assumptions to match.
A15: Set growth and year weights on Assumptions. The Forecast heatmaps and Summary update automatically.
... A37: All names, room numbers, building, and calendar dates have been removed. Labs and courses are labeled generically (Lab A, Course 1).

Sheet Registrar Projection
A1: ="Projected Registrar Use of Room A, "&Assumptions!B3 -> Projected Registrar Use of Room A, Year 4
A2: Recommended scenario: Registrar classes in the lowest-conflict standard patterns ('Open' + 'Check first'), plus open finals exam blocks. Edit assignments on the Registrar Patterns tab.
A4: Quarter | B4: Dept hours / week (forecast) | C4: Registrar class hours / week | D4: Combined hours / week | E4: Combined utilization (of 45) | F4: Registrar patterns assigned | G4: Registrar class hours / quarter | H4: Open finals exam blocks | I4: Registrar exam hours | J4: Total Registrar hours / quarter | K4: Hour-slots over 100% (check for clashes)
A5: Fall | B5: =Forecast!M11 -> 19.983333 | C5: =SUMPRODUCT('Registrar Patterns'!$I$5:$I$27,'Registrar Patterns'!$E$5:$E$27) -> 12.833333 | D5: =B5+C5 -> 32.816667 | E5: =D5/45 -> 0.72925926 | F5: =SUM('Registrar Patterns'!I5:I27) -> 5 | G5: =C5*Assumptions!$B$18 -> 128.33333 | H5: ='Finals Exam Blocks'!E23 -> 1 | I5: =H5*3 -> 3 | J5: =G5+I5 -> 131.33333 | K5: ='Combined Use'!D11 -> 9
A6: Winter | B6: =Forecast!M20 -> 19.516667 | C6: =SUMPRODUCT('Registrar Patterns'!$M$5:$M$27,'Registrar Patterns'!$E$5:$E$27) -> 10.5 | D6: =B6+C6 -> 30.016667 | E6: =D6/45 -> 0.66703704 | F6: =SUM('Registrar Patterns'!M5:M27) -> 4 | G6: =C6*Assumptions!$B$18 -> 105 | H6: ='Finals Exam Blocks'!E32 -> 2 | I6: =H6*3 -> 6 | J6: =G6+I6 -> 111 | K6: ='Combined Use'!D20 -> 4
A7: Spring | B7: =Forecast!M29 -> 18.375 | C7: =SUMPRODUCT('Registrar Patterns'!$Q$5:$Q$27,'Registrar Patterns'!$E$5:$E$27) -> 15.5 | D7: =B7+C7 -> 33.875 | E7: =D7/45 -> 0.75277778 | F7: =SUM('Registrar Patterns'!Q5:Q27) -> 6 | G7: =C7*Assumptions!$B$18 -> 155 | H7: ='Finals Exam Blocks'!E41 -> 2 | I7: =H7*3 -> 6 | J7: =G7+I7 -> 161 | K7: ='Combined Use'!D29 -> 7
A8: Summer | B8: =Forecast!M38 -> 11.25 | C8: =SUMPRODUCT('Registrar Patterns'!$U$5:$U$27,'Registrar Patterns'!$E$5:$E$27) -> 26.5 | D8: =B8+C8 -> 37.75 | E8: =D8/45 -> 0.83888889 | F8: =SUM('Registrar Patterns'!U5:U27) -> 10 | G8: =C8*Assumptions!$B$19 -> 212 | H8: 0 | I8: =H8*3 -> 0 | J8: =G8+I8 -> 212 | K8: ='Combined Use'!D38 -> 16
A9: Full year | G9: =SUM(G5:G8) -> 600.33333 | H9: =SUM(H5:H8) -> 5 | I9: =SUM(I5:I8) -> 15 | J9: =SUM(J5:J8) -> 615.33333
A11: Notes
A12: Department use is the hourly forecast; Registrar hours are scheduled class meetings in the assigned standard patterns.
A13: Many universities ask departments to limit classes starting in the 10:30 AM-2:30 PM peak; Room A's open time sits mostly outside that peak, which suits Registrar scheduling.
A14: Course Event Week (Fall Wk 3) fills 9 AM-5 PM Mon-Thu; any Registrar class in Room A would need another room that week.
A15: current fall is running ~20% below the department forecast, mainly Mon-Thu mornings. Against this fall's actual bookings, TTh 9:00-10:20 and MW 10:30-11:50 are completely free (Registrar Patterns, columns V-W).
A16: The current fall class schedule is already set, so Winter and Spring are the quarters where this projection can shape Registrar requests.
A17: Summer shows the most open time; treat its figure as a ceiling, since Summer Session demand for rooms is lower.
A18: Combined use over 100% in an hour means a historical department booking sat there in some years; confirm the slot with the department before the Registrar books it.

Sheet Backtest
A1: Backtest: forecast Year 3 using only Years 1-2, then compare with what actually happened
A2: Model = weighted average of Years 1 and 2 (same method as the live forecast). Naive = 'same as last year' (Year 2). A useful model should beat naive. | N2: Hourly backtest: share of each hour booked (typical week), Year 3 actual vs model (Years 1-2)
N3: Quarter | O3: Day | P3: Hour | Q3: Actual Y3 | R3: Model | S3: Naive | T3: Model abs err | U3: Naive abs err | V3: Model busy? | W3: Actual busy? | X3: Model correct | Y3: Naive correct
A4: Backtest weights | N4: Fall | O4: Mon | P4: 8-9 AM | Q4: =SUMIFS('Hourly Usage'!D$4:D$63,'Hourly Usage'!$A$4:$A$63,"Year 3",'Hourly Usage'!$B$4:$B$63,$N4,'Hourly Usage'!$C$4:$C$63,$O4) -> 0 | R4: =$B$5*SUMIFS('Hourly Usage'!D$4:D$63,'Hourly Usage'!$A$4:$A$63,"Year 1",'Hourly Usage'!$B$4:$B$63,$N4,'Hourly Usage'!$C$4:$C$63,$O4)+$B$6*SUMIFS('Hourly Usage'!D$4:D$63,'Hourly Usage'!$A$4:$A$63,"Year 2",'Hourly Usage'!$B$4:$B$63,$N4,'Hourly Usage'!$C$4:$C$63,$O4) -> 0.3 | S4: =SUMIFS('Hourly Usage'!D$4:D$63,'Hourly Usage'!$A$4:$A$63,"Year 2",'Hourly Usage'!$B$4:$B$63,$N4,'Hourly Usage'!$C$4:$C$63,$O4) -> 0.5 | T4: =ABS(Q4-R4) -> 0.3 | U4: =ABS(Q4-S4) -> 0.5 | V4: =IF(R4>=$B$7-0.000001,1,0) -> 0 | W4: =IF(Q4>=$B$7-0.000001,1,0) -> 0 | X4: =IF(V4=W4,1,0) -> 1 | Y4: =IF(IF(S4>=$B$7-0.000001,1,0)=W4,1,0) -> 0
A5: Weight Year 1 | B5: 0.4 | C5: Same 40/60 recent-weighting idea as the live 20/30/50, scaled to two years | N5: Fall | O5: Mon | P5: 9-10 AM | Q5: =SUMIFS('Hourly Usage'!E$4:E$63,'Hourly Usage'!$A$4:$A$63,"Year 3",'Hourly Usage'!$B$4:$B$63,$N5,'Hourly Usage'!$C$4:$C$63,$O5) -> 0 | R5: =$B$5*SUMIFS('Hourly Usage'!E$4:E$63,'Hourly Usage'!$A$4:$A$63,"Year 1",'Hourly Usage'!$B$4:$B$63,$N5,'Hourly Usage'!$C$4:$C$63,$O5)+$B$6*SUMIFS('Hourly Usage'!E$4:E$63,'Hourly Usage'!$A$4:$A$63,"Year 2",'Hourly Usage'!$B$4:$B$63,$N5,'Hourly Usage'!$C$4:$C$63,$O5) -> 1 | S5: =SUMIFS('Hourly Usage'!E$4:E$63,'Hourly Usage'!$A$4:$A$63,"Year 2",'Hourly Usage'!$B$4:$B$63,$N5,'Hourly Usage'!$C$4:$C$63,$O5) -> 1 | T5: =ABS(Q5-R5) -> 1 | U5: =ABS(Q5-S5) -> 1 | V5: =IF(R5>=$B$7-0.000001,1,0) -> 1 | W5: =IF(Q5>=$B$7-0.000001,1,0) -> 0 | X5: =IF(V5=W5,1,0) -> 0 | Y5: =IF(IF(S5>=$B$7-0.000001,1,0)=W5,1,0) -> 0
A6: Weight Year 2 | B6: 0.6 | N6: Fall | O6: Mon | P6: 10-11 AM | Q6: =SUMIFS('Hourly Usage'!F$4:F$63,'Hourly Usage'!$A$4:$A$63,"Year 3",'Hourly Usage'!$B$4:$B$63,$N6,'Hourly Usage'!$C$4:$C$63,$O6) -> 1 | R6: =$B$5*SUMIFS('Hourly Usage'!F$4:F$63,'Hourly Usage'!$A$4:$A$63,"Year 1",'Hourly Usage'!$B$4:$B$63,$N6,'Hourly Usage'!$C$4:$C$63,$O6)+$B$6*SUMIFS('Hourly Usage'!F$4:F$63,'Hourly Usage'!$A$4:$A$63,"Year 2",'Hourly Usage'!$B$4:$B$63,$N6,'Hourly Usage'!$C$4:$C$63,$O6) -> 0.7 | S6: =SUMIFS('Hourly Usage'!F$4:F$63,'Hourly Usage'!$A$4:$A$63,"Year 2",'Hourly Usage'!$B$4:$B$63,$N6,'Hourly Usage'!$C$4:$C$63,$O6) -> 0.5 | T6: =ABS(Q6-R6) -> 0.3 | U6: =ABS(Q6-S6) -> 0.5 | V6: =IF(R6>=$B$7-0.000001,1,0) -> 1 | W6: =IF(Q6>=$B$7-0.000001,1,0) -> 1 | X6: =IF(V6=W6,1,0) -> 1 | Y6: =IF(IF(S6>=$B$7-0.000001,1,0)=W6,1,0) -> 1
A7: 'Busy hour' threshold | B7: 0.5 | N7: Fall | O7: Mon | P7: 11 AM-12 PM | Q7: =SUMIFS('Hourly Usage'!G$4:G$63,'Hourly Usage'!$A$4:$A$63,"Year 3",'Hourly Usage'!$B$4:$B$63,$N7,'Hourly Usage'!$C$4:$C$63,$O7) -> 0.75 | R7: =$B$5*SUMIFS('Hourly Usage'!G$4:G$63,'Hourly Usage'!$A$4:$A$63,"Year 1",'Hourly Usage'!$B$4:$B$63,$N7,'Hourly Usage'!$C$4:$C$63,$O7)+$B$6*SUMIFS('Hourly Usage'!G$4:G$63,'Hourly Usage'!$A$4:$A$63,"Year 2",'Hourly Usage'!$B$4:$B$63,$N7,'Hourly Usage'!$C$4:$C$63,$O7) -> 0.2 | S7: =SUMIFS('Hourly Usage'!G$4:G$63,'Hourly Usage'!$A$4:$A$63,"Year 2",'Hourly Usage'!$B$4:$B$63,$N7,'Hourly Usage'!$C$4:$C$63,$O7) -> 0 | T7: =ABS(Q7-R7) -> 0.55 | U7: =ABS(Q7-S7) -> 0.75 | V7: =IF(R7>=$B$7-0.000001,1,0) -> 0 | W7: =IF(Q7>=$B$7-0.000001,1,0) -> 1 | X7: =IF(V7=W7,1,0) -> 0 | Y7: =IF(IF(S7>=$B$7-0.000001,1,0)=W7,1,0) -> 0
N8: Fall | O8: Mon | P8: 12-1 PM | Q8: =SUMIFS('Hourly Usage'!H$4:H$63,'Hourly Usage'!$A$4:$A$63,"Year 3",'Hourly Usage'!$B$4:$B$63,$N8,'Hourly Usage'!$C$4:$C$63,$O8) -> 1 | R8: =$B$5*SUMIFS('Hourly Usage'!H$4:H$63,'Hourly Usage'!$A$4:$A$63,"Year 1",'Hourly Usage'!$B$4:$B$63,$N8,'Hourly Usage'!$C$4:$C$63,$O8)+$B$6*SUMIFS('Hourly Usage'!H$4:H$63,'Hourly Usage'!$A$4:$A$63,"Year 2",'Hourly Usage'!$B$4:$B$63,$N8,'Hourly Usage'!$C$4:$C$63,$O8) -> 1 | S8: =SUMIFS('Hourly Usage'!H$4:H$63,'Hourly Usage'!$A$4:$A$63,"Year 2",'Hourly Usage'!$B$4:$B$63,$N8,'Hourly Usage'!$C$4:$C$63,$O8) -> 1 | T8: =ABS(Q8-R8) -> 0 | U8: =ABS(Q8-S8) -> 0 | V8: =IF(R8>=$B$7-0.000001,1,0) -> 1 | W8: =IF(Q8>=$B$7-0.000001,1,0) -> 1 | X8: =IF(V8=W8,1,0) -> 1 | Y8: =IF(IF(S8>=$B$7-0.000001,1,0)=W8,1,0) -> 1
A9: Headline accuracy | N9: Fall | O9: Mon | P9: 1-2 PM | Q9: =SUMIFS('Hourly Usage'!I$4:I$63,'Hourly Usage'!$A$4:$A$63,"Year 3",'Hourly Usage'!$B$4:$B$63,$N9,'Hourly Usage'!$C$4:$C$63,$O9) -> 0.5 | R9: =$B$5*SUMIFS('Hourly Usage'!I$4:I$63,'Hourly Usage'!$A$4:$A$63,"Year 1",'Hourly Usage'!$B$4:$B$63,$N9,'Hourly Usage'!$C$4:$C$63,$O9)+$B$6*SUMIFS('Hourly Usage'!I$4:I$63,'Hourly Usage'!$A$4:$A$63,"Year 2",'Hourly Usage'!$B$4:$B$63,$N9,'Hourly Usage'!$C$4:$C$63,$O9) -> 0.5 | S9: =SUMIFS('Hourly Usage'!I$4:I$63,'Hourly Usage'!$A$4:$A$63,"Year 2",'Hourly Usage'!$B$4:$B$63,$N9,'Hourly Usage'!$C$4:$C$63,$O9) -> 0.5 | T9: =ABS(Q9-R9) -> 2.6645353e-15 | U9: =ABS(Q9-S9) -> 2.6645353e-15 | V9: =IF(R9>=$B$7-0.000001,1,0) -> 1 | W9: =IF(Q9>=$B$7-0.000001,1,0) -> 1 | X9: =IF(V9=W9,1,0) -> 1 | Y9: =IF(IF(S9>=$B$7-0.000001,1,0)=W9,1,0) -> 1
A10: Metric | B10: Model | C10: Naive (last year) | D10: What it means | N10: Fall | O10: Mon | P10: 2-3 PM | Q10: =SUMIFS('Hourly Usage'!J$4:J$63,'Hourly Usage'!$A$4:$A$63,"Year 3",'Hourly Usage'!$B$4:$B$63,$N10,'Hourly Usage'!$C$4:$C$63,$O10) -> 0 | R10: =$B$5*SUMIFS('Hourly Usage'!J$4:J$63,'Hourly Usage'!$A$4:$A$63,"Year 1",'Hourly Usage'!$B$4:$B$63,$N10,'Hourly Usage'!$C$4:$C$63,$O10)+$B$6*SUMIFS('Hourly Usage'!J$4:J$63,'Hourly Usage'!$A$4:$A$63,"Year 2",'Hourly Usage'!$B$4:$B$63,$N10,'Hourly Usage'!$C$4:$C$63,$O10) -> 0 | S10: =SUMIFS('Hourly Usage'!J$4:J$63,'Hourly Usage'!$A$4:$A$63,"Year 2",'Hourly Usage'!$B$4:$B$63,$N10,'Hourly Usage'!$C$4:$C$63,$O10) -> 0 | T10: =ABS(Q10-R10) -> 0 | U10: =ABS(Q10-S10) -> 0 | V10: =IF(R10>=$B$7-0.000001,1,0) -> 0 | W10: =IF(Q10>=$B$7-0.000001,1,0) -> 0 | X10: =IF(V10=W10,1,0) -> 1 | Y10: =IF(IF(S10>=$B$7-0.000001,1,0)=W10,1,0) -> 1
A11: Weekly bookings: WAPE (total abs error / total actual) | B11: =SUM(F25:F66)/SUM(C25:C66) -> 0.21412301 | C11: =SUM(G25:G66)/SUM(C25:C66) -> 0.27334852 | D11: Typical miss on a weekly booking count, as a share of actual volume | N11: Fall | O11: Mon | P11: 3-4 PM | Q11: =SUMIFS('Hourly Usage'!K$4:K$63,'Hourly Usage'!$A$4:$A$63,"Year 3",'Hourly Usage'!$B$4:$B$63,$N11,'Hourly Usage'!$C$4:$C$63,$O11) -> 0.5 | R11: =$B$5*SUMIFS('Hourly Usage'!K$4:K$63,'Hourly Usage'!$A$4:$A$63,"Year 1",'Hourly Usage'!$B$4:$B$63,$N11,'Hourly Usage'!$C$4:$C$63,$O11)+$B$6*SUMIFS('Hourly Usage'!K$4:K$63,'Hourly Usage'!$A$4:$A$63,"Year 2",'Hourly Usage'!$B$4:$B$63,$N11,'Hourly Usage'!$C$4:$C$63,$O11) -> 0.5 | S11: =SUMIFS('Hourly Usage'!K$4:K$63,'Hourly Usage'!$A$4:$A$63,"Year 2",'Hourly Usage'!$B$4:$B$63,$N11,'Hourly Usage'!$C$4:$C$63,$O11) -> 0.5 | T11: =ABS(Q11-R11) -> 0 | U11: =ABS(Q11-S11) -> 0 | V11: =IF(R11>=$B$7-0.000001,1,0) -> 1 | W11: =IF(Q11>=$B$7-0.000001,1,0) -> 1 | X11: =IF(V11=W11,1,0) -> 1 | Y11: =IF(IF(S11>=$B$7-0.000001,1,0)=W11,1,0) -> 1
A12: Weekly bookings: mean abs error (bookings/week) | B12: =AVERAGE(F25:F66) -> 2.2380952 | C12: =AVERAGE(G25:G66) -> 2.8571429 | D12: Average miss per week, in bookings | N12: Fall | O12: Mon | P12: 4-5 PM | Q12: =SUMIFS('Hourly Usage'!L$4:L$63,'Hourly Usage'!$A$4:$A$63,"Year 3",'Hourly Usage'!$B$4:$B$63,$N12,'Hourly Usage'!$C$4:$C$63,$O12) -> 1 | R12: =$B$5*SUMIFS('Hourly Usage'!L$4:L$63,'Hourly Usage'!$A$4:$A$63,"Year 1",'Hourly Usage'!$B$4:$B$63,$N12,'Hourly Usage'!$C$4:$C$63,$O12)+$B$6*SUMIFS('Hourly Usage'!L$4:L$63,'Hourly Usage'!$A$4:$A$63,"Year 2",'Hourly Usage'!$B$4:$B$63,$N12,'Hourly Usage'!$C$4:$C$63,$O12) -> 1 | S12: =SUMIFS('Hourly Usage'!L$4:L$63,'Hourly Usage'!$A$4:$A$63,"Year 2",'Hourly Usage'!$B$4:$B$63,$N12,'Hourly Usage'!$C$4:$C$63,$O12) -> 1 | T12: =ABS(Q12-R12) -> 0 | U12: =ABS(Q12-S12) -> 0 | V12: =IF(R12>=$B$7-0.000001,1,0) -> 1 | W12: =IF(Q12>=$B$7-0.000001,1,0) -> 1 | X12: =IF(V12=W12,1,0) -> 1 | Y12: =IF(IF(S12>=$B$7-0.000001,1,0)=W12,1,0) -> 1
A13: Year 3 total bookings: forecast vs actual | B13: =SUM(D25:D66)/SUM(C25:C66)-1 -> 0.14123007 | C13: =SUM(E25:E66)/SUM(C25:C66)-1 -> 0.16400911 | D13: Annual bias; positive = over-forecast | N13: Fall | O13: Tue | P13: 8-9 AM | Q13: =SUMIFS('Hourly Usage'!D$4:D$63,'Hourly Usage'!$A$4:$A$63,"Year 3",'Hourly Usage'!$B$4:$B$63,$N13,'Hourly Usage'!$C$4:$C$63,$O13) -> 0 | R13: =$B$5*SUMIFS('Hourly Usage'!D$4:D$63,'Hourly Usage'!$A$4:$A$63,"Year 1",'Hourly Usage'!$B$4:$B$63,$N13,'Hourly Usage'!$C$4:$C$63,$O13)+$B$6*SUMIFS('Hourly Usage'!D$4:D$63,'Hourly Usage'!$A$4:$A$63,"Year 2",'Hourly Usage'!$B$4:$B$63,$N13,'Hourly Usage'!$C$4:$C$63,$O13) -> 0 | S13: =SUMIFS('Hourly Usage'!D$4:D$63,'Hourly Usage'!$A$4:$A$63,"Year 2",'Hourly Usage'!$B$4:$B$63,$N13,'Hourly Usage'!$C$4:$C$63,$O13) -> 0 | T13: =ABS(Q13-R13) -> 0 | U13: =ABS(Q13-S13) -> 0 | V13: =IF(R13>=$B$7-0.000001,1,0) -> 0 | W13: =IF(Q13>=$B$7-0.000001,1,0) -> 0 | X13: =IF(V13=W13,1,0) -> 1 | Y13: =IF(IF(S13>=$B$7-0.000001,1,0)=W13,1,0) -> 1
A14: Weekly hours: WAPE | B14: =SUM(K25:K66)/SUM(H25:H66) -> 0.21115797 | C14: =SUM(L25:L66)/SUM(H25:H66) -> 0.26477502 | D14: Typical miss on weekly hours used | N14: Fall | O14: Tue | P14: 9-10 AM | Q14: =SUMIFS('Hourly Usage'!E$4:E$63,'Hourly Usage'!$A$4:$A$63,"Year 3",'Hourly Usage'!$B$4:$B$63,$N14,'Hourly Usage'!$C$4:$C$63,$O14) -> 0 | R14: =$B$5*SUMIFS('Hourly Usage'!E$4:E$63,'Hourly Usage'!$A$4:$A$63,"Year 1",'Hourly Usage'!$B$4:$B$63,$N14,'Hourly Usage'!$C$4:$C$63,$O14)+$B$6*SUMIFS('Hourly Usage'!E$4:E$63,'Hourly Usage'!$A$4:$A$63,"Year 2",'Hourly Usage'!$B$4:$B$63,$N14,'Hourly Usage'!$C$4:$C$63,$O14) -> 0.6 | S14: =SUMIFS('Hourly Usage'!E$4:E$63,'Hourly Usage'!$A$4:$A$63,"Year 2",'Hourly Usage'!$B$4:$B$63,$N14,'Hourly Usage'!$C$4:$C$63,$O14) -> 1 | T14: =ABS(Q14-R14) -> 0.6 | U14: =ABS(Q14-S14) -> 1 | V14: =IF(R14>=$B$7-0.000001,1,0) -> 1 | W14: =IF(Q14>=$B$7-0.000001,1,0) -> 0 | X14: =IF(V14=W14,1,0) -> 0 | Y14: =IF(IF(S14>=$B$7-0.000001,1,0)=W14,1,0) -> 0
A15: Year 3 total hours: forecast vs actual | B15: =SUM(I25:I66)/SUM(H25:H66)-1 -> 0.096254615 | C15: =SUM(J25:J66)/SUM(H25:H66)-1 -> 0.13809386 | D15: Annual bias on hours | N15: Fall | O15: Tue | P15: 10-11 AM | Q15: =SUMIFS('Hourly Usage'!F$4:F$63,'Hourly Usage'!$A$4:$A$63,"Year 3",'Hourly Usage'!$B$4:$B$63,$N15,'Hourly Usage'!$C$4:$C$63,$O15) -> 0 | R15: =$B$5*SUMIFS('Hourly Usage'!F$4:F$63,'Hourly Usage'!$A$4:$A$63,"Year 1",'Hourly Usage'!$B$4:$B$63,$N15,'Hourly Usage'!$C$4:$C$63,$O15)+$B$6*SUMIFS('Hourly Usage'!F$4:F$63,'Hourly Usage'!$A$4:$A$63,"Year 2",'Hourly Usage'!$B$4:$B$63,$N15,'Hourly Usage'!$C$4:$C$63,$O15) -> 0.6 | S15: =SUMIFS('Hourly Usage'!F$4:F$63,'Hourly Usage'!$A$4:$A$63,"Year 2",'Hourly Usage'!$B$4:$B$63,$N15,'Hourly Usage'!$C$4:$C$63,$O15) -> 1 | T15: =ABS(Q15-R15) -> 0.6 | U15: =ABS(Q15-S15) -> 1 | V15: =IF(R15>=$B$7-0.000001,1,0) -> 1 | W15: =IF(Q15>=$B$7-0.000001,1,0) -> 0 | X15: =IF(V15=W15,1,0) -> 0 | Y15: =IF(IF(S15>=$B$7-0.000001,1,0)=W15,1,0) -> 0
A16: Hourly: mean abs error (share of hour) | B16: =AVERAGE(T4:T183) -> 0.30583333 | C16: =AVERAGE(U4:U183) -> 0.31435185 | D16: Average miss per hour-slot, in percentage points of the hour | N16: Fall | O16: Tue | P16: 11 AM-12 PM | Q16: =SUMIFS('Hourly Usage'!G$4:G$63,'Hourly Usage'!$A$4:$A$63,"Year 3",'Hourly Usage'!$B$4:$B$63,$N16,'Hourly Usage'!$C$4:$C$63,$O16) -> 0 | R16: =$B$5*SUMIFS('Hourly Usage'!G$4:G$63,'Hourly Usage'!$A$4:$A$63,"Year 1",'Hourly Usage'!$B$4:$B$63,$N16,'Hourly Usage'!$C$4:$C$63,$O16)+$B$6*SUMIFS('Hourly Usage'!G$4:G$63,'Hourly Usage'!$A$4:$A$63,"Year 2",'Hourly Usage'!$B$4:$B$63,$N16,'Hourly Usage'!$C$4:$C$63,$O16) -> 0.6 | S16: =SUMIFS('Hourly Usage'!G$4:G$63,'Hourly Usage'!$A$4:$A$63,"Year 2",'Hourly Usage'!$B$4:$B$63,$N16,'Hourly Usage'!$C$4:$C$63,$O16) -> 1 | T16: =ABS(Q16-R16) -> 0.6 | U16: =ABS(Q16-S16) -> 1 | V16: =IF(R16>=$B$7-0.000001,1,0) -> 1 | W16: =IF(Q16>=$B$7-0.000001,1,0) -> 0 | X16: =IF(V16=W16,1,0) -> 0 | Y16: =IF(IF(S16>=$B$7-0.000001,1,0)=W16,1,0) -> 0
A17: Hourly: busy/open called correctly | B17: =AVERAGE(X4:X183) -> 0.66111111 | C17: =AVERAGE(Y4:Y183) -> 0.64444444 | D17: Share of 180 weekday hour-slots where the model correctly predicted busy (>= threshold) vs open | N17: Fall | O17: Tue | P17: 12-1 PM | Q17: =SUMIFS('Hourly Usage'!H$4:H$63,'Hourly Usage'!$A$4:$A$63,"Year 3",'Hourly Usage'!$B$4:$B$63,$N17,'Hourly Usage'!$C$4:$C$63,$O17) -> 0 | R17: =$B$5*SUMIFS('Hourly Usage'!H$4:H$63,'Hourly Usage'!$A$4:$A$63,"Year 1",'Hourly Usage'!$B$4:$B$63,$N17,'Hourly Usage'!$C$4:$C$63,$O17)+$B$6*SUMIFS('Hourly Usage'!H$4:H$63,'Hourly Usage'!$A$4:$A$63,"Year 2",'Hourly Usage'!$B$4:$B$63,$N17,'Hourly Usage'!$C$4:$C$63,$O17) -> 0.7 | S17: =SUMIFS('Hourly Usage'!H$4:H$63,'Hourly Usage'!$A$4:$A$63,"Year 2",'Hourly Usage'!$B$4:$B$63,$N17,'Hourly Usage'!$C$4:$C$63,$O17) -> 0.5 | T17: =ABS(Q17-R17) -> 0.7 | U17: =ABS(Q17-S17) -> 0.5 | V17: =IF(R17>=$B$7-0.000001,1,0) -> 1 | W17: =IF(Q17>=$B$7-0.000001,1,0) -> 0 | X17: =IF(V17=W17,1,0) -> 0 | Y17: =IF(IF(S17>=$B$7-0.000001,1,0)=W17,1,0) -> 0
N18: Fall | O18: Tue | P18: 1-2 PM | Q18: =SUMIFS('Hourly Usage'!I$4:I$63,'Hourly Usage'!$A$4:$A$63,"Year 3",'Hourly Usage'!$B$4:$B$63,$N18,'Hourly Usage'!$C$4:$C$63,$O18) -> 1 | R18: =$B$5*SUMIFS('Hourly Usage'!I$4:I$63,'Hourly Usage'!$A$4:$A$63,"Year 1",'Hourly Usage'!$B$4:$B$63,$N18,'Hourly Usage'!$C$4:$C$63,$O18)+$B$6*SUMIFS('Hourly Usage'!I$4:I$63,'Hourly Usage'!$A$4:$A$63,"Year 2",'Hourly Usage'!$B$4:$B$63,$N18,'Hourly Usage'!$C$4:$C$63,$O18) -> 1 | S18: =SUMIFS('Hourly Usage'!I$4:I$63,'Hourly Usage'!$A$4:$A$63,"Year 2",'Hourly Usage'!$B$4:$B$63,$N18,'Hourly Usage'!$C$4:$C$63,$O18) -> 1 | T18: =ABS(Q18-R18) -> 0 | U18: =ABS(Q18-S18) -> 0 | V18: =IF(R18>=$B$7-0.000001,1,0) -> 1 | W18: =IF(Q18>=$B$7-0.000001,1,0) -> 1 | X18: =IF(V18=W18,1,0) -> 1 | Y18: =IF(IF(S18>=$B$7-0.000001,1,0)=W18,1,0) -> 1
A19: Note: hourly backtest uses one sampled mid-quarter week per quarter per year, so it measures how well the recurring weekly pattern carries over year to year. | N19: Fall | O19: Tue | P19: 2-3 PM | Q19: =SUMIFS('Hourly Usage'!J$4:J$63,'Hourly Usage'!$A$4:$A$63,"Year 3",'Hourly Usage'!$B$4:$B$63,$N19,'Hourly Usage'!$C$4:$C$63,$O19) -> 1 | R19: =$B$5*SUMIFS('Hourly Usage'!J$4:J$63,'Hourly Usage'!$A$4:$A$63,"Year 1",'Hourly Usage'!$B$4:$B$63,$N19,'Hourly Usage'!$C$4:$C$63,$O19)+$B$6*SUMIFS('Hourly Usage'!J$4:J$63,'Hourly Usage'!$A$4:$A$63,"Year 2",'Hourly Usage'!$B$4:$B$63,$N19,'Hourly Usage'!$C$4:$C$63,$O19) -> 0.6 | S19: =SUMIFS('Hourly Usage'!J$4:J$63,'Hourly Usage'!$A$4:$A$63,"Year 2",'Hourly Usage'!$B$4:$B$63,$N19,'Hourly Usage'!$C$4:$C$63,$O19) -> 1 | T19: =ABS(Q19-R19) -> 0.4 | U19: =ABS(Q19-S19) -> 0 | V19: =IF(R19>=$B$7-0.000001,1,0) -> 1 | W19: =IF(Q19>=$B$7-0.000001,1,0) -> 1 | X19: =IF(V19=W19,1,0) -> 1 | Y19: =IF(IF(S19>=$B$7-0.000001,1,0)=W19,1,0) -> 1
A20: Live check: the current fall's actual weeks are tracked on the 'Current Fall Actual' tab. | N20: Fall | O20: Tue | P20: 3-4 PM | Q20: =SUMIFS('Hourly Usage'!K$4:K$63,'Hourly Usage'!$A$4:$A$63,"Year 3",'Hourly Usage'!$B$4:$B$63,$N20,'Hourly Usage'!$C$4:$C$63,$O20) -> 0.5 | R20: =$B$5*SUMIFS('Hourly Usage'!K$4:K$63,'Hourly Usage'!$A$4:$A$63,"Year 1",'Hourly Usage'!$B$4:$B$63,$N20,'Hourly Usage'!$C$4:$C$63,$O20)+$B$6*SUMIFS('Hourly Usage'!K$4:K$63,'Hourly Usage'!$A$4:$A$63,"Year 2",'Hourly Usage'!$B$4:$B$63,$N20,'Hourly Usage'!$C$4:$C$63,$O20) -> 1 | S20: =SUMIFS('Hourly Usage'!K$4:K$63,'Hourly Usage'!$A$4:$A$63,"Year 2",'Hourly Usage'!$B$4:$B$63,$N20,'Hourly Usage'!$C$4:$C$63,$O20) -> 1 | T20: =ABS(Q20-R20) -> 0.5 | U20: =ABS(Q20-S20) -> 0.5 | V20: =IF(R20>=$B$7-0.000001,1,0) -> 1 | W20: =IF(Q20>=$B$7-0.000001,1,0) -> 1 | X20: =IF(V20=W20,1,0) -> 1 | Y20: =IF(IF(S20>=$B$7-0.000001,1,0)=W20,1,0) -> 1
N21: Fall | O21: Tue | P21: 4-5 PM | Q21: =SUMIFS('Hourly Usage'!L$4:L$63,'Hourly Usage'!$A$4:$A$63,"Year 3",'Hourly Usage'!$B$4:$B$63,$N21,'Hourly Usage'!$C$4:$C$63,$O21) -> 0 | R21: =$B$5*SUMIFS('Hourly Usage'!L$4:L$63,'Hourly Usage'!$A$4:$A$63,"Year 1",'Hourly Usage'!$B$4:$B$63,$N21,'Hourly Usage'!$C$4:$C$63,$O21)+$B$6*SUMIFS('Hourly Usage'!L$4:L$63,'Hourly Usage'!$A$4:$A$63,"Year 2",'Hourly Usage'!$B$4:$B$63,$N21,'Hourly Usage'!$C$4:$C$63,$O21) -> 0.5 | S21: =SUMIFS('Hourly Usage'!L$4:L$63,'Hourly Usage'!$A$4:$A$63,"Year 2",'Hourly Usage'!$B$4:$B$63,$N21,'Hourly Usage'!$C$4:$C$63,$O21) -> 0.5 | T21: =ABS(Q21-R21) -> 0.5 | U21: =ABS(Q21-S21) -> 0.5 | V21: =IF(R21>=$B$7-0.000001,1,0) -> 1 | W21: =IF(Q21>=$B$7-0.000001,1,0) -> 0 | X21: =IF(V21=W21,1,0) -> 0 | Y21: =IF(IF(S21>=$B$7-0.000001,1,0)=W21,1,0) -> 0
N22: Fall | O22: Wed | P22: 8-9 AM | Q22: =SUMIFS('Hourly Usage'!D$4:D$63,'Hourly Usage'!$A$4:$A$63,"Year 3",'Hourly Usage'!$B$4:$B$63,$N22,'Hourly Usage'!$C$4:$C$63,$O22) -> 0 | R22: =$B$5*SUMIFS('Hourly Usage'!D$4:D$63,'Hourly Usage'!$A$4:$A$63,"Year 1",'Hourly Usage'!$B$4:$B$63,$N22,'Hourly Usage'!$C$4:$C$63,$O22)+$B$6*SUMIFS('Hourly Usage'!D$4:D$63,'Hourly Usage'!$A$4:$A$63,"Year 2",'Hourly Usage'!$B$4:$B$63,$N22,'Hourly Usage'!$C$4:$C$63,$O22) -> 0 | S22: =SUMIFS('Hourly Usage'!D$4:D$63,'Hourly Usage'!$A$4:$A$63,"Year 2",'Hourly Usage'!$B$4:$B$63,$N22,'Hourly Usage'!$C$4:$C$63,$O22) -> 0 | T22: =ABS(Q22-R22) -> 0 | U22: =ABS(Q22-S22) -> 0 | V22: =IF(R22>=$B$7-0.000001,1,0) -> 0 | W22: =IF(Q22>=$B$7-0.000001,1,0) -> 0 | X22: =IF(V22=W22,1,0) -> 1 | Y22: =IF(IF(S22>=$B$7-0.000001,1,0)=W22,1,0) -> 1
N23: Fall | O23: Wed | P23: 9-10 AM | Q23: =SUMIFS('Hourly Usage'!E$4:E$63,'Hourly Usage'!$A$4:$A$63,"Year 3",'Hourly Usage'!$B$4:$B$63,$N23,'Hourly Usage'!$C$4:$C$63,$O23) -> 0 | R23: =$B$5*SUMIFS('Hourly Usage'!E$4:E$63,'Hourly Usage'!$A$4:$A$63,"Year 1",'Hourly Usage'!$B$4:$B$63,$N23,'Hourly Usage'!$C$4:$C$63,$O23)+$B$6*SUMIFS('Hourly Usage'!E$4:E$63,'Hourly Usage'!$A$4:$A$63,"Year 2",'Hourly Usage'!$B$4:$B$63,$N23,'Hourly Usage'!$C$4:$C$63,$O23) -> 0.4 | S23: =SUMIFS('Hourly Usage'!E$4:E$63,'Hourly Usage'!$A$4:$A$63,"Year 2",'Hourly Usage'!$B$4:$B$63,$N23,'Hourly Usage'!$C$4:$C$63,$O23) -> 0 | T23: =ABS(Q23-R23) -> 0.4 | U23: =ABS(Q23-S23) -> 0 | V23: =IF(R23>=$B$7-0.000001,1,0) -> 0 | W23: =IF(Q23>=$B$7-0.000001,1,0) -> 0 | X23: =IF(V23=W23,1,0) -> 1 | Y23: =IF(IF(S23>=$B$7-0.000001,1,0)=W23,1,0) -> 1
A24: Quarter | B24: Week | C24: Actual Y3 bookings | D24: Model forecast | E24: Naive forecast | F24: Model abs error | G24: Naive abs error | H24: Actual Y3 hours | I24: Model hours | J24: Naive hours | K24: Model abs error (hrs) | L24: Naive abs error (hrs) | N24: Fall | O24: Wed | P24: 10-11 AM | Q24: =SUMIFS('Hourly Usage'!F$4:F$63,'Hourly Usage'!$A$4:$A$63,"Year 3",'Hourly Usage'!$B$4:$B$63,$N24,'Hourly Usage'!$C$4:$C$63,$O24) -> 0 | R24: =$B$5*SUMIFS('Hourly Usage'!F$4:F$63,'Hourly Usage'!$A$4:$A$63,"Year 1",'Hourly Usage'!$B$4:$B$63,$N24,'Hourly Usage'!$C$4:$C$63,$O24)+$B$6*SUMIFS('Hourly Usage'!F$4:F$63,'Hourly Usage'!$A$4:$A$63,"Year 2",'Hourly Usage'!$B$4:$B$63,$N24,'Hourly Usage'!$C$4:$C$63,$O24) -> 0.4 | S24: =SUMIFS('Hourly Usage'!F$4:F$63,'Hourly Usage'!$A$4:$A$63,"Year 2",'Hourly Usage'!$B$4:$B$63,$N24,'Hourly Usage'!$C$4:$C$63,$O24) -> 0 | T24: =ABS(Q24-R24) -> 0.4 | U24: =ABS(Q24-S24) -> 0 | V24: =IF(R24>=$B$7-0.000001,1,0) -> 0 | W24: =IF(Q24>=$B$7-0.000001,1,0) -> 0 | X24: =IF(V24=W24,1,0) -> 1 | Y24: =IF(IF(S24>=$B$7-0.000001,1,0)=W24,1,0) -> 1
A25: ='Weekly History'!A3 -> Fall | B25: ='Weekly History'!B3 -> Fall Wk 1 | C25: ='Weekly History'!E3 -> 10 | D25: =$B$5*'Weekly History'!C3+$B$6*'Weekly History'!D3 -> 11.4 | E25: ='Weekly History'!D3 -> 11 | F25: =ABS(C25-D25) -> 1.4 | G25: =ABS(C25-E25) -> 1 | H25: ='Weekly History'!H3 -> 16.290909 | I25: =$B$5*'Weekly History'!F3+$B$6*'Weekly History'!G3 -> 21.07 | J25: ='Weekly History'!G3 -> 21.25 | K25: =ABS(H25-I25) -> 4.7790909 | L25: =ABS(H25-J25) -> 4.9590909 | N25: Fall | O25: Wed | P25: 11 AM-12 PM | Q25: =SUMIFS('Hourly Usage'!G$4:G$63,'Hourly Usage'!$A$4:$A$63,"Year 3",'Hourly Usage'!$B$4:$B$63,$N25,'Hourly Usage'!$C$4:$C$63,$O25) -> 0 | R25: =$B$5*SUMIFS('Hourly Usage'!G$4:G$63,'Hourly Usage'!$A$4:$A$63,"Year 1",'Hourly Usage'!$B$4:$B$63,$N25,'Hourly Usage'!$C$4:$C$63,$O25)+$B$6*SUMIFS('Hourly Usage'!G$4:G$63,'Hourly Usage'!$A$4:$A$63,"Year 2",'Hourly Usage'!$B$4:$B$63,$N25,'Hourly Usage'!$C$4:$C$63,$O25) -> 0.2 | S25: =SUMIFS('Hourly Usage'!G$4:G$63,'Hourly Usage'!$A$4:$A$63,"Year 2",'Hourly Usage'!$B$4:$B$63,$N25,'Hourly Usage'!$C$4:$C$63,$O25) -> 0 | T25: =ABS(Q25-R25) -> 0.2 | U25: =ABS(Q25-S25) -> 0 | V25: =IF(R25>=$B$7-0.000001,1,0) -> 0 | W25: =IF(Q25>=$B$7-0.000001,1,0) -> 0 | X25: =IF(V25=W25,1,0) -> 1 | Y25: =IF(IF(S25>=$B$7-0.000001,1,0)=W25,1,0) -> 1
A26: ='Weekly History'!A4 -> Fall | B26: ='Weekly History'!B4 -> Fall Wk 2 | C26: ='Weekly History'!E4 -> 12 | D26: =$B$5*'Weekly History'!C4+$B$6*'Weekly History'!D4 -> 11.4 | E26: ='Weekly History'!D4 -> 11 | F26: =ABS(C26-D26) -> 0.6 | G26: =ABS(C26-E26) -> 1 | H26: ='Weekly History'!H4 -> 19.549091 | I26: =$B$5*'Weekly History'!F4+$B$6*'Weekly History'!G4 -> 21.07 | J26: ='Weekly History'!G4 -> 21.25 | K26: =ABS(H26-I26) -> 1.5209091 | L26: =ABS(H26-J26) -> 1.7009091 | N26: Fall | O26: Wed | P26: 12-1 PM | Q26: =SUMIFS('Hourly Usage'!H$4:H$63,'Hourly Usage'!$A$4:$A$63,"Year 3",'Hourly Usage'!$B$4:$B$63,$N26,'Hourly Usage'!$C$4:$C$63,$O26) -> 1 | R26: =$B$5*SUMIFS('Hourly Usage'!H$4:H$63,'Hourly Usage'!$A$4:$A$63,"Year 1",'Hourly Usage'!$B$4:$B$63,$N26,'Hourly Usage'!$C$4:$C$63,$O26)+$B$6*SUMIFS('Hourly Usage'!H$4:H$63,'Hourly Usage'!$A$4:$A$63,"Year 2",'Hourly Usage'!$B$4:$B$63,$N26,'Hourly Usage'!$C$4:$C$63,$O26) -> 1 | S26: =SUMIFS('Hourly Usage'!H$4:H$63,'Hourly Usage'!$A$4:$A$63,"Year 2",'Hourly Usage'!$B$4:$B$63,$N26,'Hourly Usage'!$C$4:$C$63,$O26) -> 1 | T26: =ABS(Q26-R26) -> 0 | U26: =ABS(Q26-S26) -> 0 | V26: =IF(R26>=$B$7-0.000001,1,0) -> 1 | W26: =IF(Q26>=$B$7-0.000001,1,0) -> 1 | X26: =IF(V26=W26,1,0) -> 1 | Y26: =IF(IF(S26>=$B$7-0.000001,1,0)=W26,1,0) -> 1
A27: ='Weekly History'!A5 -> Fall | B27: ='Weekly History'!B5 -> Fall Wk 3 | C27: ='Weekly History'!E5 -> 15 | D27: =$B$5*'Weekly History'!C5+$B$6*'Weekly History'!D5 -> 14.8 | E27: ='Weekly History'!D5 -> 14 | F27: =ABS(C27-D27) -> 0.2 | G27: =ABS(C27-E27) -> 1 | H27: ='Weekly History'!H5 -> 24.436364 | I27: =$B$5*'Weekly History'!F5+$B$6*'Weekly History'!G5 -> 27.320606 | J27: ='Weekly History'!G5 -> 27.045455 | K27: =ABS(H27-I27) -> 2.8842424 | L27: =ABS(H27-J27) -> 2.6090909 | N27: Fall | O27: Wed | P27: 1-2 PM | Q27: =SUMIFS('Hourly Usage'!I$4:I$63,'Hourly Usage'!$A$4:$A$63,"Year 3",'Hourly Usage'!$B$4:$B$63,$N27,'Hourly Usage'!$C$4:$C$63,$O27) -> 0.5 | R27: =$B$5*SUMIFS('Hourly Usage'!I$4:I$63,'Hourly Usage'!$A$4:$A$63,"Year 1",'Hourly Usage'!$B$4:$B$63,$N27,'Hourly Usage'!$C$4:$C$63,$O27)+$B$6*SUMIFS('Hourly Usage'!I$4:I$63,'Hourly Usage'!$A$4:$A$63,"Year 2",'Hourly Usage'!$B$4:$B$63,$N27,'Hourly Usage'!$C$4:$C$63,$O27) -> 0.35 | S27: =SUMIFS('Hourly Usage'!I$4:I$63,'Hourly Usage'!$A$4:$A$63,"Year 2",'Hourly Usage'!$B$4:$B$63,$N27,'Hourly Usage'!$C$4:$C$63,$O27) -> 0.25 | T27: =ABS(Q27-R27) -> 0.15 | U27: =ABS(Q27-S27) -> 0.25 | V27: =IF(R27>=$B$7-0.000001,1,0) -> 0 | W27: =IF(Q27>=$B$7-0.000001,1,0) -> 1 | X27: =IF(V27=W27,1,0) -> 0 | Y27: =IF(IF(S27>=$B$7-0.000001,1,0)=W27,1,0) -> 0
A28: ='Weekly History'!A6 -> Fall | B28: ='Weekly History'!B6 -> Fall Wk 4 | C28: ='Weekly History'!E6 -> 12 | D28: =$B$5*'Weekly History'!C6+$B$6*'Weekly History'!D6 -> 12.4 | E28: ='Weekly History'!D6 -> 12 | F28: =ABS(C28-D28) -> 0.4 | G28: =ABS(C28-E28) -> 0 | H28: ='Weekly History'!H6 -> 19.549091 | I28: =$B$5*'Weekly History'!F6+$B$6*'Weekly History'!G6 -> 22.922424 | J28: ='Weekly History'!G6 -> 23.181818 | K28: =ABS(H28-I28) -> 3.3733333 | L28: =ABS(H28-J28) -> 3.6327273 | N28: Fall | O28: Wed | P28: 2-3 PM | Q28: =SUMIFS('Hourly Usage'!J$4:J$63,'Hourly Usage'!$A$4:$A$63,"Year 3",'Hourly Usage'!$B$4:$B$63,$N28,'Hourly Usage'!$C$4:$C$63,$O28) -> 0 | R28: =$B$5*SUMIFS('Hourly Usage'!J$4:J$63,'Hourly Usage'!$A$4:$A$63,"Year 1",'Hourly Usage'!$B$4:$B$63,$N28,'Hourly Usage'!$C$4:$C$63,$O28)+$B$6*SUMIFS('Hourly Usage'!J$4:J$63,'Hourly Usage'!$A$4:$A$63,"Year 2",'Hourly Usage'!$B$4:$B$63,$N28,'Hourly Usage'!$C$4:$C$63,$O28) -> 0.4 | S28: =SUMIFS('Hourly Usage'!J$4:J$63,'Hourly Usage'!$A$4:$A$63,"Year 2",'Hourly Usage'!$B$4:$B$63,$N28,'Hourly Usage'!$C$4:$C$63,$O28) -> 0 | T28: =ABS(Q28-R28) -> 0.4 | U28: =ABS(Q28-S28) -> 0 | V28: =IF(R28>=$B$7-0.000001,1,0) -> 0 | W28: =IF(Q28>=$B$7-0.000001,1,0) -> 0 | X28: =IF(V28=W28,1,0) -> 1 | Y28: =IF(IF(S28>=$B$7-0.000001,1,0)=W28,1,0) -> 1
A29: ='Weekly History'!A7 -> Fall | B29: ='Weekly History'!B7 -> Fall Wk 5 | C29: ='Weekly History'!E7 -> 11 | D29: =$B$5*'Weekly History'!C7+$B$6*'Weekly History'!D7 -> 12.6 | E29: ='Weekly History'!D7 -> 11 | F29: =ABS(C29-D29) -> 1.6 | G29: =ABS(C29-E29) -> 0 | H29: ='Weekly History'!H7 -> 17.92 | I29: =$B$5*'Weekly History'!F7+$B$6*'Weekly History'!G7 -> 23.15 | J29: ='Weekly History'!G7 -> 21.25 | K29: =ABS(H29-I29) -> 5.23 | L29: =ABS(H29-J29) -> 3.33 | N29: Fall | O29: Wed | P29: 3-4 PM | Q29: =SUMIFS('Hourly Usage'!K$4:K$63,'Hourly Usage'!$A$4:$A$63,"Year 3",'Hourly Usage'!$B$4:$B$63,$N29,'Hourly Usage'!$C$4:$C$63,$O29) -> 0.5 | R29: =$B$5*SUMIFS('Hourly Usage'!K$4:K$63,'Hourly Usage'!$A$4:$A$63,"Year 1",'Hourly Usage'!$B$4:$B$63,$N29,'Hourly Usage'!$C$4:$C$63,$O29)+$B$6*SUMIFS('Hourly Usage'!K$4:K$63,'Hourly Usage'!$A$4:$A$63,"Year 2",'Hourly Usage'!$B$4:$B$63,$N29,'Hourly Usage'!$C$4:$C$63,$O29) -> 0.4 | S29: =SUMIFS('Hourly Usage'!K$4:K$63,'Hourly Usage'!$A$4:$A$63,"Year 2",'Hourly Usage'!$B$4:$B$63,$N29,'Hourly Usage'!$C$4:$C$63,$O29) -> 0 | T29: =ABS(Q29-R29) -> 0.1 | U29: =ABS(Q29-S29) -> 0.5 | V29: =IF(R29>=$B$7-0.000001,1,0) -> 0 | W29: =IF(Q29>=$B$7-0.000001,1,0) -> 1 | X29: =IF(V29=W29,1,0) -> 0 | Y29: =IF(IF(S29>=$B$7-0.000001,1,0)=W29,1,0) -> 0
A30: ='Weekly History'!A8 -> Fall | B30: ='Weekly History'!B8 -> Fall Wk 6 | C30: ='Weekly History'!E8 -> 13 | D30: =$B$5*'Weekly History'!C8+$B$6*'Weekly History'!D8 -> 12.8 | E30: ='Weekly History'!D8 -> 12 | F30: =ABS(C30-D30) -> 0.2 | G30: =ABS(C30-E30) -> 1 | H30: ='Weekly History'!H8 -> 21.178182 | I30: =$B$5*'Weekly History'!F8+$B$6*'Weekly History'!G8 -> 23.615758 | J30: ='Weekly History'!G8 -> 23.181818 | K30: =ABS(H30-I30) -> 2.4375758 | L30: =ABS(H30-J30) -> 2.0036364 | N30: Fall | O30: Wed | P30: 4-5 PM | Q30: =SUMIFS('Hourly Usage'!L$4:L$63,'Hourly Usage'!$A$4:$A$63,"Year 3",'Hourly Usage'!$B$4:$B$63,$N30,'Hourly Usage'!$C$4:$C$63,$O30) -> 1 | R30: =$B$5*SUMIFS('Hourly Usage'!L$4:L$63,'Hourly Usage'!$A$4:$A$63,"Year 1",'Hourly Usage'!$B$4:$B$63,$N30,'Hourly Usage'!$C$4:$C$63,$O30)+$B$6*SUMIFS('Hourly Usage'!L$4:L$63,'Hourly Usage'!$A$4:$A$63,"Year 2",'Hourly Usage'!$B$4:$B$63,$N30,'Hourly Usage'!$C$4:$C$63,$O30) -> 0.4 | S30: =SUMIFS('Hourly Usage'!L$4:L$63,'Hourly Usage'!$A$4:$A$63,"Year 2",'Hourly Usage'!$B$4:$B$63,$N30,'Hourly Usage'!$C$4:$C$63,$O30) -> 0 | T30: =ABS(Q30-R30) -> 0.6 | U30: =ABS(Q30-S30) -> 1 | V30: =IF(R30>=$B$7-0.000001,1,0) -> 0 | W30: =IF(Q30>=$B$7-0.000001,1,0) -> 1 | X30: =IF(V30=W30,1,0) -> 0 | Y30: =IF(IF(S30>=$B$7-0.000001,1,0)=W30,1,0) -> 0
A31: ='Weekly History'!A9 -> Fall | B31: ='Weekly History'!B9 -> Fall Wk 7 | C31: ='Weekly History'!E9 -> 15 | D31: =$B$5*'Weekly History'!C9+$B$6*'Weekly History'!D9 -> 14 | E31: ='Weekly History'!D9 -> 14 | F31: =ABS(C31-D31) -> 1 | G31: =ABS(C31-E31) -> 1 | H31: ='Weekly History'!H9 -> 24.436364 | I31: =$B$5*'Weekly History'!F9+$B$6*'Weekly History'!G9 -> 25.933939 | J31: ='Weekly History'!G9 -> 27.045455 | K31: =ABS(H31-I31) -> 1.4975758 | L31: =ABS(H31-J31) -> 2.6090909 | N31: Fall | O31: Thu | P31: 8-9 AM | Q31: =SUMIFS('Hourly Usage'!D$4:D$63,'Hourly Usage'!$A$4:$A$63,"Year 3",'Hourly Usage'!$B$4:$B$63,$N31,'Hourly Usage'!$C$4:$C$63,$O31) -> 0 | R31: =$B$5*SUMIFS('Hourly Usage'!D$4:D$63,'Hourly Usage'!$A$4:$A$63,"Year 1",'Hourly Usage'!$B$4:$B$63,$N31,'Hourly Usage'!$C$4:$C$63,$O31)+$B$6*SUMIFS('Hourly Usage'!D$4:D$63,'Hourly Usage'!$A$4:$A$63,"Year 2",'Hourly Usage'!$B$4:$B$63,$N31,'Hourly Usage'!$C$4:$C$63,$O31) -> 0 | S31: =SUMIFS('Hourly Usage'!D$4:D$63,'Hourly Usage'!$A$4:$A$63,"Year 2",'Hourly Usage'!$B$4:$B$63,$N31,'Hourly Usage'!$C$4:$C$63,$O31) -> 0 | T31: =ABS(Q31-R31) -> 0 | U31: =ABS(Q31-S31) -> 0 | V31: =IF(R31>=$B$7-0.000001,1,0) -> 0 | W31: =IF(Q31>=$B$7-0.000001,1,0) -> 0 | X31: =IF(V31=W31,1,0) -> 1 | Y31: =IF(IF(S31>=$B$7-0.000001,1,0)=W31,1,0) -> 1
A32: ='Weekly History'!A10 -> Fall | B32: ='Weekly History'!B10 -> Fall Wk 8 | C32: ='Weekly History'!E10 -> 14 | D32: =$B$5*'Weekly History'!C10+$B$6*'Weekly History'!D10 -> 12.8 | E32: ='Weekly History'!D10 -> 12 | F32: =ABS(C32-D32) -> 1.2 | G32: =ABS(C32-E32) -> 2 | H32: ='Weekly History'!H10 -> 22.807273 | I32: =$B$5*'Weekly History'!F10+$B$6*'Weekly History'!G10 -> 23.615758 | J32: ='Weekly History'!G10 -> 23.181818 | K32: =ABS(H32-I32) -> 0.80848485 | L32: =ABS(H32-J32) -> 0.37454545 | N32: Fall | O32: Thu | P32: 9-10 AM | Q32: =SUMIFS('Hourly Usage'!E$4:E$63,'Hourly Usage'!$A$4:$A$63,"Year 3",'Hourly Usage'!$B$4:$B$63,$N32,'Hourly Usage'!$C$4:$C$63,$O32) -> 0 | R32: =$B$5*SUMIFS('Hourly Usage'!E$4:E$63,'Hourly Usage'!$A$4:$A$63,"Year 1",'Hourly Usage'!$B$4:$B$63,$N32,'Hourly Usage'!$C$4:$C$63,$O32)+$B$6*SUMIFS('Hourly Usage'!E$4:E$63,'Hourly Usage'!$A$4:$A$63,"Year 2",'Hourly Usage'!$B$4:$B$63,$N32,'Hourly Usage'!$C$4:$C$63,$O32) -> 0.6 | S32: =SUMIFS('Hourly Usage'!E$4:E$63,'Hourly Usage'!$A$4:$A$63,"Year 2",'Hourly Usage'!$B$4:$B$63,$N32,'Hourly Usage'!$C$4:$C$63,$O32) -> 1 | T32: =ABS(Q32-R32) -> 0.6 | U32: =ABS(Q32-S32) -> 1 | V32: =IF(R32>=$B$7-0.000001,1,0) -> 1 | W32: =IF(Q32>=$B$7-0.000001,1,0) -> 0 | X32: =IF(V32=W32,1,0) -> 0 | Y32: =IF(IF(S32>=$B$7-0.000001,1,0)=W32,1,0) -> 0
A33: ='Weekly History'!A11 -> Fall | B33: ='Weekly History'!B11 -> Fall Wk 9 | C33: ='Weekly History'!E11 -> 15 | D33: =$B$5*'Weekly History'!C11+$B$6*'Weekly History'!D11 -> 11.6 | E33: ='Weekly History'!D11 -> 10 | F33: =ABS(C33-D33) -> 3.4 | G33: =ABS(C33-E33) -> 5 | H33: ='Weekly History'!H11 -> 24.436364 | I33: =$B$5*'Weekly History'!F11+$B$6*'Weekly History'!G11 -> 21.297576 | J33: ='Weekly History'!G11 -> 19.318182 | K33: =ABS(H33-I33) -> 3.1387879 | L33: =ABS(H33-J33) -> 5.1181818 | N33: Fall | O33: Thu | P33: 10-11 AM | Q33: =SUMIFS('Hourly Usage'!F$4:F$63,'Hourly Usage'!$A$4:$A$63,"Year 3",'Hourly Usage'!$B$4:$B$63,$N33,'Hourly Usage'!$C$4:$C$63,$O33) -> 0 | R33: =$B$5*SUMIFS('Hourly Usage'!F$4:F$63,'Hourly Usage'!$A$4:$A$63,"Year 1",'Hourly Usage'!$B$4:$B$63,$N33,'Hourly Usage'!$C$4:$C$63,$O33)+$B$6*SUMIFS('Hourly Usage'!F$4:F$63,'Hourly Usage'!$A$4:$A$63,"Year 2",'Hourly Usage'!$B$4:$B$63,$N33,'Hourly Usage'!$C$4:$C$63,$O33) -> 0.6 | S33: =SUMIFS('Hourly Usage'!F$4:F$63,'Hourly Usage'!$A$4:$A$63,"Year 2",'Hourly Usage'!$B$4:$B$63,$N33,'Hourly Usage'!$C$4:$C$63,$O33) -> 1 | T33: =ABS(Q33-R33) -> 0.6 | U33: =ABS(Q33-S33) -> 1 | V33: =IF(R33>=$B$7-0.000001,1,0) -> 1 | W33: =IF(Q33>=$B$7-0.000001,1,0) -> 0 | X33: =IF(V33=W33,1,0) -> 0 | Y33: =IF(IF(S33>=$B$7-0.000001,1,0)=W33,1,0) -> 0
A34: ='Weekly History'!A12 -> Fall | B34: ='Weekly History'!B12 -> Fall Thanksgiving | C34: ='Weekly History'!E12 -> 13 | D34: =$B$5*'Weekly History'!C12+$B$6*'Weekly History'!D12 -> 11.6 | E34: ='Weekly History'!D12 -> 10 | F34: =ABS(C34-D34) -> 1.4 | G34: =ABS(C34-E34) -> 3 | H34: ='Weekly History'!H12 -> 21.178182 | I34: =$B$5*'Weekly History'!F12+$B$6*'Weekly History'!G12 -> 21.297576 | J34: ='Weekly History'!G12 -> 19.318182 | K34: =ABS(H34-I34) -> 0.11939394 | L34: =ABS(H34-J34) -> 1.86 | N34: Fall | O34: Thu | P34: 11 AM-12 PM | Q34: =SUMIFS('Hourly Usage'!G$4:G$63,'Hourly Usage'!$A$4:$A$63,"Year 3",'Hourly Usage'!$B$4:$B$63,$N34,'Hourly Usage'!$C$4:$C$63,$O34) -> 0 | R34: =$B$5*SUMIFS('Hourly Usage'!G$4:G$63,'Hourly Usage'!$A$4:$A$63,"Year 1",'Hourly Usage'!$B$4:$B$63,$N34,'Hourly Usage'!$C$4:$C$63,$O34)+$B$6*SUMIFS('Hourly Usage'!G$4:G$63,'Hourly Usage'!$A$4:$A$63,"Year 2",'Hourly Usage'!$B$4:$B$63,$N34,'Hourly Usage'!$C$4:$C$63,$O34) -> 0.6 | S34: =SUMIFS('Hourly Usage'!G$4:G$63,'Hourly Usage'!$A$4:$A$63,"Year 2",'Hourly Usage'!$B$4:$B$63,$N34,'Hourly Usage'!$C$4:$C$63,$O34) -> 1 | T34: =ABS(Q34-R34) -> 0.6 | U34: =ABS(Q34-S34) -> 1 | V34: =IF(R34>=$B$7-0.000001,1,0) -> 1 | W34: =IF(Q34>=$B$7-0.000001,1,0) -> 0 | X34: =IF(V34=W34,1,0) -> 0 | Y34: =IF(IF(S34>=$B$7-0.000001,1,0)=W34,1,0) -> 0
A35: ='Weekly History'!A13 -> Fall | B35: ='Weekly History'!B13 -> Fall Wk 10 | C35: ='Weekly History'!E13 -> 14 | D35: =$B$5*'Weekly History'!C13+$B$6*'Weekly History'!D13 -> 15.2 | E35: ='Weekly History'!D13 -> 16 | F35: =ABS(C35-D35) -> 1.2 | G35: =ABS(C35-E35) -> 2 | H35: ='Weekly History'!H13 -> 22.807273 | I35: =$B$5*'Weekly History'!F13+$B$6*'Weekly History'!G13 -> 28.252121 | J35: ='Weekly History'!G13 -> 30.909091 | K35: =ABS(H35-I35) -> 5.4448485 | L35: =ABS(H35-J35) -> 8.1018182 | N35: Fall | O35: Thu | P35: 12-1 PM | Q35: =SUMIFS('Hourly Usage'!H$4:H$63,'Hourly Usage'!$A$4:$A$63,"Year 3",'Hourly Usage'!$B$4:$B$63,$N35,'Hourly Usage'!$C$4:$C$63,$O35) -> 1 | R35: =$B$5*SUMIFS('Hourly Usage'!H$4:H$63,'Hourly Usage'!$A$4:$A$63,"Year 1",'Hourly Usage'!$B$4:$B$63,$N35,'Hourly Usage'!$C$4:$C$63,$O35)+$B$6*SUMIFS('Hourly Usage'!H$4:H$63,'Hourly Usage'!$A$4:$A$63,"Year 2",'Hourly Usage'!$B$4:$B$63,$N35,'Hourly Usage'!$C$4:$C$63,$O35) -> 1 | S35: =SUMIFS('Hourly Usage'!H$4:H$63,'Hourly Usage'!$A$4:$A$63,"Year 2",'Hourly Usage'!$B$4:$B$63,$N35,'Hourly Usage'!$C$4:$C$63,$O35) -> 1 | T35: =ABS(Q35-R35) -> 0 | U35: =ABS(Q35-S35) -> 0 | V35: =IF(R35>=$B$7-0.000001,1,0) -> 1 | W35: =IF(Q35>=$B$7-0.000001,1,0) -> 1 | X35: =IF(V35=W35,1,0) -> 1 | Y35: =IF(IF(S35>=$B$7-0.000001,1,0)=W35,1,0) -> 1
A36: ='Weekly History'!A14 -> Fall | B36: ='Weekly History'!B14 -> Fall Finals | C36: ='Weekly History'!E14 -> 12 | D36: =$B$5*'Weekly History'!C14+$B$6*'Weekly History'!D14 -> 13 | E36: ='Weekly History'!D14 -> 13 | F36: =ABS(C36-D36) -> 1 | G36: =ABS(C36-E36) -> 1 | H36: ='Weekly History'!H14 -> 19.549091 | I36: =$B$5*'Weekly History'!F14+$B$6*'Weekly History'!G14 -> 24.081515 | J36: ='Weekly History'!G14 -> 25.113636 | K36: =ABS(H36-I36) -> 4.5324242 | L36: =ABS(H36-J36) -> 5.5645455 | N36: Fall | O36: Thu | P36: 1-2 PM | Q36: =SUMIFS('Hourly Usage'!I$4:I$63,'Hourly Usage'!$A$4:$A$63,"Year 3",'Hourly Usage'!$B$4:$B$63,$N36,'Hourly Usage'!$C$4:$C$63,$O36) -> 0.66666667 | R36: =$B$5*SUMIFS('Hourly Usage'!I$4:I$63,'Hourly Usage'!$A$4:$A$63,"Year 1",'Hourly Usage'!$B$4:$B$63,$N36,'Hourly Usage'!$C$4:$C$63,$O36)+$B$6*SUMIFS('Hourly Usage'!I$4:I$63,'Hourly Usage'!$A$4:$A$63,"Year 2",'Hourly Usage'!$B$4:$B$63,$N36,'Hourly Usage'!$C$4:$C$63,$O36) -> 0.5 | S36: =SUMIFS('Hourly Usage'!I$4:I$63,'Hourly Usage'!$A$4:$A$63,"Year 2",'Hourly Usage'!$B$4:$B$63,$N36,'Hourly Usage'!$C$4:$C$63,$O36) -> 0.5 | T36: =ABS(Q36-R36) -> 0.16666667 | U36: =ABS(Q36-S36) -> 0.16666667 | V36: =IF(R36>=$B$7-0.000001,1,0) -> 1 | W36: =IF(Q36>=$B$7-0.000001,1,0) -> 1 | X36: =IF(V36=W36,1,0) -> 1 | Y36: =IF(IF(S36>=$B$7-0.000001,1,0)=W36,1,0) -> 1
A37: ='Weekly History'!A15 -> Winter | B37: ='Weekly History'!B15 -> Winter Wk 1 | C37: ='Weekly History'!E15 -> 10 | D37: =$B$5*'Weekly History'!C15+$B$6*'Weekly History'!D15 -> 13.2 | E37: ='Weekly History'!D15 -> 14 | F37: =ABS(C37-D37) -> 3.2 | G37: =ABS(C37-E37) -> 4 | H37: ='Weekly History'!H15 -> 16.6 | I37: =$B$5*'Weekly History'!F15+$B$6*'Weekly History'!G15 -> 19.528154 | J37: ='Weekly History'!G15 -> 20.75 | K37: =ABS(H37-I37) -> 2.9281538 | L37: =ABS(H37-J37) -> 4.15 | N37: Fall | O37: Thu | P37: 2-3 PM | Q37: =SUMIFS('Hourly Usage'!J$4:J$63,'Hourly Usage'!$A$4:$A$63,"Year 3",'Hourly Usage'!$B$4:$B$63,$N37,'Hourly Usage'!$C$4:$C$63,$O37) -> 0 | R37: =$B$5*SUMIFS('Hourly Usage'!J$4:J$63,'Hourly Usage'!$A$4:$A$63,"Year 1",'Hourly Usage'!$B$4:$B$63,$N37,'Hourly Usage'!$C$4:$C$63,$O37)+$B$6*SUMIFS('Hourly Usage'!J$4:J$63,'Hourly Usage'!$A$4:$A$63,"Year 2",'Hourly Usage'!$B$4:$B$63,$N37,'Hourly Usage'!$C$4:$C$63,$O37) -> 0 | S37: =SUMIFS('Hourly Usage'!J$4:J$63,'Hourly Usage'!$A$4:$A$63,"Year 2",'Hourly Usage'!$B$4:$B$63,$N37,'Hourly Usage'!$C$4:$C$63,$O37) -> 0 | T37: =ABS(Q37-R37) -> 0 | U37: =ABS(Q37-S37) -> 0 | V37: =IF(R37>=$B$7-0.000001,1,0) -> 0 | W37: =IF(Q37>=$B$7-0.000001,1,0) -> 0 | X37: =IF(V37=W37,1,0) -> 1 | Y37: =IF(IF(S37>=$B$7-0.000001,1,0)=W37,1,0) -> 1
A38: ='Weekly History'!A16 -> Winter | B38: ='Weekly History'!B16 -> Winter Wk 2 | C38: ='Weekly History'!E16 -> 11 | D38: =$B$5*'Weekly History'!C16+$B$6*'Weekly History'!D16 -> 13 | E38: ='Weekly History'!D16 -> 13 | F38: =ABS(C38-D38) -> 2 | G38: =ABS(C38-E38) -> 2 | H38: ='Weekly History'!H16 -> 18.26 | I38: =$B$5*'Weekly History'!F16+$B$6*'Weekly History'!G16 -> 19.228714 | J38: ='Weekly History'!G16 -> 19.267857 | K38: =ABS(H38-I38) -> 0.96871429 | L38: =ABS(H38-J38) -> 1.0078571 | N38: Fall | O38: Thu | P38: 3-4 PM | Q38: =SUMIFS('Hourly Usage'!K$4:K$63,'Hourly Usage'!$A$4:$A$63,"Year 3",'Hourly Usage'!$B$4:$B$63,$N38,'Hourly Usage'!$C$4:$C$63,$O38) -> 1 | R38: =$B$5*SUMIFS('Hourly Usage'!K$4:K$63,'Hourly Usage'!$A$4:$A$63,"Year 1",'Hourly Usage'!$B$4:$B$63,$N38,'Hourly Usage'!$C$4:$C$63,$O38)+$B$6*SUMIFS('Hourly Usage'!K$4:K$63,'Hourly Usage'!$A$4:$A$63,"Year 2",'Hourly Usage'!$B$4:$B$63,$N38,'Hourly Usage'!$C$4:$C$63,$O38) -> 1 | S38: =SUMIFS('Hourly Usage'!K$4:K$63,'Hourly Usage'!$A$4:$A$63,"Year 2",'Hourly Usage'!$B$4:$B$63,$N38,'Hourly Usage'!$C$4:$C$63,$O38) -> 1 | T38: =ABS(Q38-R38) -> 0 | U38: =ABS(Q38-S38) -> 0 | V38: =IF(R38>=$B$7-0.000001,1,0) -> 1 | W38: =IF(Q38>=$B$7-0.000001,1,0) -> 1 | X38: =IF(V38=W38,1,0) -> 1 | Y38: =IF(IF(S38>=$B$7-0.000001,1,0)=W38,1,0) -> 1
A39: ='Weekly History'!A17 -> Winter | B39: ='Weekly History'!B17 -> Winter Wk 3 | C39: ='Weekly History'!E17 -> 12 | D39: =$B$5*'Weekly History'!C17+$B$6*'Weekly History'!D17 -> 16.8 | E39: ='Weekly History'!D17 -> 16 | F39: =ABS(C39-D39) -> 4.8 | G39: =ABS(C39-E39) -> 4 | H39: ='Weekly History'!H17 -> 19.92 | I39: =$B$5*'Weekly History'!F17+$B$6*'Weekly History'!G17 -> 24.845802 | J39: ='Weekly History'!G17 -> 23.714286 | K39: =ABS(H39-I39) -> 4.9258022 | L39: =ABS(H39-J39) -> 3.7942857 | N39: Fall | O39: Thu | P39: 4-5 PM | Q39: =SUMIFS('Hourly Usage'!L$4:L$63,'Hourly Usage'!$A$4:$A$63,"Year 3",'Hourly Usage'!$B$4:$B$63,$N39,'Hourly Usage'!$C$4:$C$63,$O39) -> 0 | R39: =$B$5*SUMIFS('Hourly Usage'!L$4:L$63,'Hourly Usage'!$A$4:$A$63,"Year 1",'Hourly Usage'!$B$4:$B$63,$N39,'Hourly Usage'!$C$4:$C$63,$O39)+$B$6*SUMIFS('Hourly Usage'!L$4:L$63,'Hourly Usage'!$A$4:$A$63,"Year 2",'Hourly Usage'!$B$4:$B$63,$N39,'Hourly Usage'!$C$4:$C$63,$O39) -> 0.2 | S39: =SUMIFS('Hourly Usage'!L$4:L$63,'Hourly Usage'!$A$4:$A$63,"Year 2",'Hourly Usage'!$B$4:$B$63,$N39,'Hourly Usage'!$C$4:$C$63,$O39) -> 0 | T39: =ABS(Q39-R39) -> 0.2 | U39: =ABS(Q39-S39) -> 0 | V39: =IF(R39>=$B$7-0.000001,1,0) -> 0 | W39: =IF(Q39>=$B$7-0.000001,1,0) -> 0 | X39: =IF(V39=W39,1,0) -> 1 | Y39: =IF(IF(S39>=$B$7-0.000001,1,0)=W39,1,0) -> 1
A40: ='Weekly History'!A18 -> Winter | B40: ='Weekly History'!B18 -> Winter Wk 4 | C40: ='Weekly History'!E18 -> 11 | D40: =$B$5*'Weekly History'!C18+$B$6*'Weekly History'!D18 -> 14 | E40: ='Weekly History'!D18 -> 14 | F40: =ABS(C40-D40) -> 3 | G40: =ABS(C40-E40) -> 3 | H40: ='Weekly History'!H18 -> 18.26 | I40: =$B$5*'Weekly History'!F18+$B$6*'Weekly History'!G18 -> 20.707846 | J40: ='Weekly History'!G18 -> 20.75 | K40: =ABS(H40-I40) -> 2.4478462 | L40: =ABS(H40-J40) -> 2.49 | N40: Fall | O40: Fri | P40: 8-9 AM | Q40: =SUMIFS('Hourly Usage'!D$4:D$63,'Hourly Usage'!$A$4:$A$63,"Year 3",'Hourly Usage'!$B$4:$B$63,$N40,'Hourly Usage'!$C$4:$C$63,$O40) -> 0 | R40: =$B$5*SUMIFS('Hourly Usage'!D$4:D$63,'Hourly Usage'!$A$4:$A$63,"Year 1",'Hourly Usage'!$B$4:$B$63,$N40,'Hourly Usage'!$C$4:$C$63,$O40)+$B$6*SUMIFS('Hourly Usage'!D$4:D$63,'Hourly Usage'!$A$4:$A$63,"Year 2",'Hourly Usage'!$B$4:$B$63,$N40,'Hourly Usage'!$C$4:$C$63,$O40) -> 0 | S40: =SUMIFS('Hourly Usage'!D$4:D$63,'Hourly Usage'!$A$4:$A$63,"Year 2",'Hourly Usage'!$B$4:$B$63,$N40,'Hourly Usage'!$C$4:$C$63,$O40) -> 0 | T40: =ABS(Q40-R40) -> 0 | U40: =ABS(Q40-S40) -> 0 | V40: =IF(R40>=$B$7-0.000001,1,0) -> 0 | W40: =IF(Q40>=$B$7-0.000001,1,0) -> 0 | X40: =IF(V40=W40,1,0) -> 1 | Y40: =IF(IF(S40>=$B$7-0.000001,1,0)=W40,1,0) -> 1
...

Sheet Summary
A1: ="Room A Hourly Usage Summary, "&Assumptions!B3 -> Room A Hourly Usage Summary, Year 4
A3: Quarter | B3: Typical-week hours booked (8-5) | C3: Room utilization (of 45 hrs) | D3: Busy hour-slots per week | E3: Busiest hour of day | F3: Avg use in busiest hour | G3: Quietest hour of day | H3: Free hours per week
A4: Fall | B4: =Forecast!M11 -> 19.983333 | C4: =B4/45 -> 0.44407407 | D4: =Forecast!C11 -> 10 | E4: =INDEX(Forecast!$D$5:$L$5,MATCH(MAX(Forecast!D11:L11),Forecast!D11:L11,0)) -> 12-1 PM | F4: =MAX(Forecast!D11:L11) -> 0.81 | G4: =INDEX(Forecast!$D$5:$L$5,MATCH(MIN(Forecast!D11:L11),Forecast!D11:L11,0)) -> 8-9 AM | H4: =Forecast!N11 -> 25.016667
A5: Winter | B5: =Forecast!M20 -> 19.516667 | C5: =B5/45 -> 0.4337037 | D5: =Forecast!C20 -> 10 | E5: =INDEX(Forecast!$D$5:$L$5,MATCH(MAX(Forecast!D20:L20),Forecast!D20:L20,0)) -> 12-1 PM | F5: =MAX(Forecast!D20:L20) -> 0.86 | G5: =INDEX(Forecast!$D$5:$L$5,MATCH(MIN(Forecast!D20:L20),Forecast!D20:L20,0)) -> 8-9 AM | H5: =Forecast!N20 -> 25.483333
A6: Spring | B6: =Forecast!M29 -> 18.375 | C6: =B6/45 -> 0.40833333 | D6: =Forecast!C29 -> 10 | E6: =INDEX(Forecast!$D$5:$L$5,MATCH(MAX(Forecast!D29:L29),Forecast!D29:L29,0)) -> 3-4 PM | F6: =MAX(Forecast!D29:L29) -> 0.65 | G6: =INDEX(Forecast!$D$5:$L$5,MATCH(MIN(Forecast!D29:L29),Forecast!D29:L29,0)) -> 8-9 AM | H6: =Forecast!N29 -> 26.625
A7: Summer | B7: =Forecast!M38 -> 11.25 | C7: =B7/45 -> 0.25 | D7: =Forecast!C38 -> 6 | E7: =INDEX(Forecast!$D$5:$L$5,MATCH(MAX(Forecast!D38:L38),Forecast!D38:L38,0)) -> 12-1 PM | F7: =MAX(Forecast!D38:L38) -> 0.51 | G7: =INDEX(Forecast!$D$5:$L$5,MATCH(MIN(Forecast!D38:L38),Forecast!D38:L38,0)) -> 8-9 AM | H7: =Forecast!N38 -> 33.75
A9: Average use by hour of day (all weekdays)
A10: Quarter | B10: 8-9 AM | C10: 9-10 AM | D10: 10-11 AM | E10: 11 AM-12 PM | F10: 12-1 PM | G10: 1-2 PM | H10: 2-3 PM | I10: 3-4 PM | J10: 4-5 PM
A11: Fall | B11: =Forecast!D11 -> 0.03 | C11: =Forecast!E11 -> 0.4 | D11: =Forecast!F11 -> 0.47 | E11: =Forecast!G11 -> 0.285 | F11: =Forecast!H11 -> 0.81 | G11: =Forecast!I11 -> 0.50166667 | H11: =Forecast!J11 -> 0.2 | I11: =Forecast!K11 -> 0.69 | J11: =Forecast!L11 -> 0.61
A12: Winter | B12: =Forecast!D20 -> 0 | C12: =Forecast!E20 -> 0.25 | D12: =Forecast!F20 -> 0.25 | E12: =Forecast!G20 -> 0.265 | F12: =Forecast!H20 -> 0.86 | G12: =Forecast!I20 -> 0.64166667 | H12: =Forecast!J20 -> 0.38666667 | I12: =Forecast!K20 -> 0.65 | J12: =Forecast!L20 -> 0.6
A13: Spring | B13: =Forecast!D29 -> 0.05 | C13: =Forecast!E29 -> 0.36 | D13: =Forecast!F29 -> 0.26 | E13: =Forecast!G29 -> 0.21 | F13: =Forecast!H29 -> 0.64 | G13: =Forecast!I29 -> 0.455 | H13: =Forecast!J29 -> 0.41 | I13: =Forecast!K29 -> 0.65 | J13: =Forecast!L29 -> 0.64
A14: Summer | B14: =Forecast!D38 -> 0 | C14: =Forecast!E38 -> 0.21 | D14: =Forecast!F38 -> 0.29 | E14: =Forecast!G38 -> 0.33 | F14: =Forecast!H38 -> 0.51 | G14: =Forecast!I38 -> 0.34 | H14: =Forecast!J38 -> 0.11 | I14: =Forecast!K38 -> 0.2 | J14: =Forecast!L38 -> 0.26
A16: current fall check: typical-week hours actual vs forecast
A17: Actual (Wks 1, 2, 4 average) | B17: ='Current Fall Actual'!M10 -> 15.833333
A18: Forecast | B18: =Forecast!M11 -> 19.983333
A19: Difference | B19: =B17/B18-1 -> -0.20767306

Sheet Assumptions
A1: Assumptions
A2: Assumption | B2: Value | C2: Notes
A3: Forecast year | B3: Year 4
A4: Growth in usage | B4: 0 | C4: Scales every hourly forecast; results are capped at 100%
A5: Weight: Year 1 | B5: 0.2
A6: Weight: Year 2 | B6: 0.3
A7: Weight: Year 3 | B7: 0.5 | C7: Most recent year weighted highest
A8: Sample weeks per quarter-year in the log | B8: 1 | C8: Usage is divided by this; raise it if you add more sample weeks per quarter
A9: current fall weeks in the actual log | B9: 3 | C9: Weeks of Sep 21, Sep 28, Oct 12 (Course Event Week excluded)
A10: 'Busy hour' threshold | B10: 0.75 | C10: Hour slots at or above this share booked count as busy
A13: Registrar projection settings
A14: Setting | B14: Value | C14: Notes
A15: 'Open': expected department use at or below | B15: 0.2 | C15: Expected = average projected department use across the minutes the pattern covers
A16: ...and worst-case hour at or below | B16: 0.5 | C16: Worst-case = highest projected use in any hour the pattern touches
A17: 'Check first': expected department use at or below | B17: 0.35 | C17: Some weeks may clash; confirm with the department before booking
A18: Instruction weeks per quarter (Fall/Winter/Spring) | B18: 10 | C18: 10 weeks of instruction
A19: Instruction weeks, Summer | B19: 8 | C19: Summer quarter
A20: Room seats | B20: 36 | C20: Fits seminars, discussion sections, and small exams

Sheet Registrar Patterns
A1: Registrar Standard Meeting Patterns vs. Projected Department Use
A2: Expected = average projected department use over the minutes the pattern covers. Worst-case = busiest hour it touches. Assign = 1 adds the pattern to the Registrar projection (recommended scenario shown; change freely).
A4: Pattern | B4: Days | C4: Start | D4: End | E4: Hours / week | F4: Fall expected | G4: Fall worst-case | H4: Fall status | I4: Fall assign (1/0) | J4: Winter expected | K4: Winter worst-case | L4: Winter status | M4: Winter assign (1/0) | N4: Spring expected | O4: Spring worst-case | P4: Spring status | Q4: Spring assign (1/0) | R4: Summer expected | S4: Summer worst-case | T4: Summer status | U4: Summer assign (1/0) | V4: current fall actual: expected use | W4: current fall actual: worst-case
A5: MWF 50 min | B5: Mon,Wed,Fri | C5: 0.35416667 | D5: 0.38888889 | E5: =(LEN(B5)-LEN(SUBSTITUTE(B5,",",""))+1)*(MIN(D5,17/24)-MAX(C5,8/24))*24 -> 2.5 | F5: =IFERROR(SUMPRODUCT(ISNUMBER(SEARCH(Forecast!$B$6:$B$10,$B5))*(((((($D5*24)+Forecast!$D$3:$L$3+1-ABS(($D5*24)-Forecast!$D$3:$L$3-1))/2)-((($C5*24)+Forecast!$D$3:$L$3+ABS(($C5*24)-Forecast!$D$3:$L$3))/2))+ABS((((($D5*24)+Forecast!$D$3:$L$3+1-ABS(($D5*24)-Forecast!$D$3:$L$3-1))/2)-((($C5*24)+Forecast!$D$3:$L$3+ABS(($C5*24)-Forecast!$D$3:$L$3))/2))))/2)*Forecast!$D$6:$L$10)/SUMPRODUCT(ISNUMBER(SEARCH(Forecast!$B$6:$B$10,$B5))*(((((($D5*24)+Forecast!$D$3:$L$3+1-ABS(($D5*24)-Forecast!$D$3:$L$3-1))/2)-((($C5*24)+Forecast!$D$3:$L$3+ABS(($C5*24)-Forecast!$D$3:$L$3))/2))+ABS((((($D5*24)+Forecast!$D$3:$L$3+1-ABS(($D5*24)-Forecast!$D$3:$L$3-1))/2)-((($C5*24)+Forecast!$D$3:$L$3+ABS(($C5*24)-Forecast!$D$3:$L$3))/2))))/2)),0) -> 0.21666667 | G5: =SUMPRODUCT(MAX(ISNUMBER(SEARCH(Forecast!$B$6:$B$10,$B5))*(Forecast!$D$3:$L$3<($D5*24))*(Forecast!$D$3:$L$3+1>($C5*24))*Forecast!$D$6:$L$10)) -> 0.7 | H5: =IF(AND(F5<=Assumptions!$B$15,G5<=Assumptions!$B$16),"Open",IF(F5<=Assumptions!$B$17,"Check first","Conflict")) -> Check first | I5: 1 | J5: =IFERROR(SUMPRODUCT(ISNUMBER(SEARCH(Forecast!$B$15:$B$19,$B5))*(((((($D5*24)+Forecast!$D$3:$L$3+1-ABS(($D5*24)-Forecast!$D$3:$L$3-1))/2)-((($C5*24)+Forecast!$D$3:$L$3+ABS(($C5*24)-Forecast!$D$3:$L$3))/2))+ABS((((($D5*24)+Forecast!$D$3:$L$3+1-ABS(($D5*24)-Forecast!$D$3:$L$3-1))/2)-((($C5*24)+Forecast!$D$3:$L$3+ABS(($C5*24)-Forecast!$D$3:$L$3))/2))))/2)*Forecast!$D$15:$L$19)/SUMPRODUCT(ISNUMBER(SEARCH(Forecast!$B$15:$B$19,$B5))*(((((($D5*24)+Forecast!$D$3:$L$3+1-ABS(($D5*24)-Forecast!$D$3:$L$3-1))/2)-((($C5*24)+Forecast!$D$3:$L$3+ABS(($C5*24)-Forecast!$D$3:$L$3))/2))+ABS((((($D5*24)+Forecast!$D$3:$L$3+1-ABS(($D5*24)-Forecast!$D$3:$L$3-1))/2)-((($C5*24)+Forecast!$D$3:$L$3+ABS(($C5*24)-Forecast!$D$3:$L$3))/2))))/2)),0) -> 0.15333333 | K5: =SUMPRODUCT(MAX(ISNUMBER(SEARCH(Forecast!$B$15:$B$19,$B5))*(Forecast!$D$3:$L$3<($D5*24))*(Forecast!$D$3:$L$3+1>($C5*24))*Forecast!$D$15:$L$19)) -> 0.5 | L5: =IF(AND(J5<=Assumptions!$B$15,K5<=Assumptions!$B$16),"Open",IF(J5<=Assumptions!$B$17,"Check first","Conflict")) -> Open | M5: 1 | N5: =IFERROR(SUMPRODUCT(ISNUMBER(SEARCH(Forecast!$B$24:$B$28,$B5))*(((((($D5*24)+Forecast!$D$3:$L$3+1-ABS(($D5*24)-Forecast!$D$3:$L$3-1))/2)-((($C5*24)+Forecast!$D$3:$L$3+ABS(($C5*24)-Forecast!$D$3:$L$3))/2))+ABS((((($D5*24)+Forecast!$D$3:$L$3+1-ABS(($D5*24)-Forecast!$D$3:$L$3-1))/2)-((($C5*24)+Forecast!$D$3:$L$3+ABS(($C5*24)-Forecast!$D$3:$L$3))/2))))/2)*Forecast!$D$24:$L$28)/SUMPRODUCT(ISNUMBER(SEARCH(Forecast!$B$24:$B$28,$B5))*(((((($D5*24)+Forecast!$D$3:$L$3+1-ABS(($D5*24)-Forecast!$D$3:$L$3-1))/2)-((($C5*24)+Forecast!$D$3:$L$3+ABS(($C5*24)-Forecast!$D$3:$L$3))/2))+ABS((((($D5*24)+Forecast!$D$3:$L$3+1-ABS(($D5*24)-Forecast!$D$3:$L$3-1))/2)-((($C5*24)+Forecast!$D$3:$L$3+ABS(($C5*24)-Forecast!$D$3:$L$3))/2))))/2)),0) -> 0.29 | O5: =SUMPRODUCT(MAX(ISNUMBER(SEARCH(Forecast!$B$24:$B$28,$B5))*(Forecast!$D$3:$L$3<($D5*24))*(Forecast!$D$3:$L$3+1>($C5*24))*Forecast!$D$24:$L$28)) -> 0.8 | P5: =IF(AND(N5<=Assumptions!$B$15,O5<=Assumptions!$B$16),"Open",IF(N5<=Assumptions!$B$17,"Check first","Conflict")) -> Check first | Q5: 1 | R5: =IFERROR(SUMPRODUCT(ISNUMBER(SEARCH(Forecast!$B$33:$B$37,$B5))*(((((($D5*24)+Forecast!$D$3:$L$3+1-ABS(($D5*24)-Forecast!$D$3:$L$3-1))/2)-((($C5*24)+Forecast!$D$3:$L$3+ABS(($C5*24)-Forecast!$D$3:$L$3))/2))+ABS((((($D5*24)+Forecast!$D$3:$L$3+1-ABS(($D5*24)-Forecast!$D$3:$L$3-1))/2)-((($C5*24)+Forecast!$D$3:$L$3+ABS(($C5*24)-Forecast!$D$3:$L$3))/2))))/2)*Forecast!$D$33:$L$37)/SUMPRODUCT(ISNUMBER(SEARCH(Forecast!$B$33:$B$37,$B5))*(((((($D5*24)+Forecast!$D$3:$L$3+1-ABS(($D5*24)-Forecast!$D$3:$L$3-1))/2)-((($C5*24)+Forecast!$D$3:$L$3+ABS(($C5*24)-Forecast!$D$3:$L$3))/2))+ABS((((($D5*24)+Forecast!$D$3:$L$3+1-ABS(($D5*24)-Forecast!$D$3:$L$3-1))/2)-((($C5*24)+Forecast!$D$3:$L$3+ABS(($C5*24)-Forecast!$D$3:$L$3))/2))))/2)),0) -> 0.14 | S5: =SUMPRODUCT(MAX(ISNUMBER(SEARCH(Forecast!$B$33:$B$37,$B5))*(Forecast!$D$3:$L$3<($D5*24))*(Forecast!$D$3:$L$3+1>($C5*24))*Forecast!$D$33:$L$37)) -> 0.8 | T5: =IF(AND(R5<=Assumptions!$B$15,S5<=Assumptions!$B$16),"Open",IF(R5<=Assumptions!$B$17,"Check first","Conflict")) -> Check first | U5: 1 | V5: =IFERROR(SUMPRODUCT(ISNUMBER(SEARCH('Current Fall Actual'!$B$5:$B$9,$B5))*(((((($D5*24)+Forecast!$D$3:$L$3+1-ABS(($D5*24)-Forecast!$D$3:$L$3-1))/2)-((($C5*24)+Forecast!$D$3:$L$3+ABS(($C5*24)-Forecast!$D$3:$L$3))/2))+ABS((((($D5*24)+Forecast!$D$3:$L$3+1-ABS(($D5*24)-Forecast!$D$3:$L$3-1))/2)-((($C5*24)+Forecast!$D$3:$L$3+ABS(($C5*24)-Forecast!$D$3:$L$3))/2))))/2)*'Current Fall Actual'!$D$5:$L$9)/SUMPRODUCT(ISNUMBER(SEARCH('Current Fall Actual'!$B$5:$B$9,$B5))*(((((($D5*24)+Forecast!$D$3:$L$3+1-ABS(($D5*24)-Forecast!$D$3:$L$3-1))/2)-((($C5*24)+Forecast!$D$3:$L$3+ABS(($C5*24)-Forecast!$D$3:$L$3))/2))+ABS((((($D5*24)+Forecast!$D$3:$L$3+1-ABS(($D5*24)-Forecast!$D$3:$L$3-1))/2)-((($C5*24)+Forecast!$D$3:$L$3+ABS(($C5*24)-Forecast!$D$3:$L$3))/2))))/2)),0) -> 0.13333333 | W5: =SUMPRODUCT(MAX(ISNUMBER(SEARCH('Current Fall Actual'!$B$5:$B$9,$B5))*(Forecast!$D$3:$L$3<($D5*24))*(Forecast!$D$3:$L$3+1>($C5*24))*'Current Fall Actual'!$D$5:$L$9)) -> 1
